2022-05-20 19:00:01,727 - (-2147418111, 'Call was rejected by callee.', None, None)
Traceback (most recent call last):
  File "C:\Users\allan.mesquita\OneDrive - NTT\Documents\Projetos\Automacao_Evidencias\Script\connect_sql.py", line 39, in <module>
    chavenf_entrada = str(aba_tblrec.Range(f'A{linha}'))
  File "<COMObject <unknown>>", line 2, in Range
pywintypes.com_error: (-2147418111, 'Call was rejected by callee.', None, None)
