2022-06-23 13:00:08,134 - (-2147418111, 'Call was rejected by callee.', None, None)
Traceback (most recent call last):
  File "C:\Users\allan.mesquita\OneDrive - NTT\Documents\Projetos\Automacao_Evidencias\Script\main_qualidade2.py", line 161, in <module>
    aba_tblPA.Range(f'D{var_linha}').Value = datetime.strftime(datetime.now(), '%d/%m/%Y %H:%M')
  File "C:\Users\allan.mesquita\AppData\Local\Packages\PythonSoftwareFoundation.Python.3.10_qbz5n2kfra8p0\LocalCache\local-packages\Python310\site-packages\win32com\client\dynamic.py", line 686, in __setattr__
    self._oleobj_.Invoke(entry.dispid, 0, invoke_type, 0, value)
pywintypes.com_error: (-2147418111, 'Call was rejected by callee.', None, None)
