2022-07-27 15:27:54,309 - [Errno 13] Permission denied: 'C:\\Users\\allan.mesquita\\OneDrive - NTT\\Privado\\GESTÃO DE ESTOQUE\\100 BcoDados\\003 Evidencias\\01 Processamento\\TERCA VIX - Para Teste_202207131524 32220728268233000784550010001859401000182252_Recebimento.xlsx'
Traceback (most recent call last):
  File "C:/Users/allan.mesquita/OneDrive - NTT/Documents/Projetos/Automacao_Evidencias/Script/main_qualidade2.py", line 90, in <module>
    wb = xl.load_workbook(path + file_name)
  File "C:\Users\allan.mesquita\AppData\Local\Packages\PythonSoftwareFoundation.Python.3.10_qbz5n2kfra8p0\LocalCache\local-packages\Python310\site-packages\openpyxl\reader\excel.py", line 315, in load_workbook
    reader = ExcelReader(filename, read_only, keep_vba,
  File "C:\Users\allan.mesquita\AppData\Local\Packages\PythonSoftwareFoundation.Python.3.10_qbz5n2kfra8p0\LocalCache\local-packages\Python310\site-packages\openpyxl\reader\excel.py", line 124, in __init__
    self.archive = _validate_archive(fn)
  File "C:\Users\allan.mesquita\AppData\Local\Packages\PythonSoftwareFoundation.Python.3.10_qbz5n2kfra8p0\LocalCache\local-packages\Python310\site-packages\openpyxl\reader\excel.py", line 96, in _validate_archive
    archive = ZipFile(filename, 'r')
  File "C:\Program Files\WindowsApps\PythonSoftwareFoundation.Python.3.10_3.10.1520.0_x64__qbz5n2kfra8p0\lib\zipfile.py", line 1249, in __init__
    self.fp = io.open(file, filemode)
PermissionError: [Errno 13] Permission denied: 'C:\\Users\\allan.mesquita\\OneDrive - NTT\\Privado\\GESTÃO DE ESTOQUE\\100 BcoDados\\003 Evidencias\\01 Processamento\\TERCA VIX - Para Teste_202207131524 32220728268233000784550010001859401000182252_Recebimento.xlsx'
