2022-05-10 11:58:05,410 - [Errno 2] No such file or directory: 'C:\\Users\\allan.mesquita\\NTT\\@AM BR Services and Operations - Privado\\GESTÃO DE ESTOQUE\\100 BcoDados\\003 Evidencias\\06 Lixeira\\Testes\\01 Processamento202204051510 33220305437734000580550010000026611100018356_Expedição.xlsx'
Traceback (most recent call last):
  File "C:\Users\allan.mesquita\OneDrive - NTT\Documents\Projetos\Automacao_Evidencias\Script\Test_ZOne\main_qualidade2.py", line 67, in <module>
    wb = xl.load_workbook(path + file_name)
  File "C:\Users\allan.mesquita\AppData\Local\Packages\PythonSoftwareFoundation.Python.3.10_qbz5n2kfra8p0\LocalCache\local-packages\Python310\site-packages\openpyxl\reader\excel.py", line 315, in load_workbook
    reader = ExcelReader(filename, read_only, keep_vba,
  File "C:\Users\allan.mesquita\AppData\Local\Packages\PythonSoftwareFoundation.Python.3.10_qbz5n2kfra8p0\LocalCache\local-packages\Python310\site-packages\openpyxl\reader\excel.py", line 124, in __init__
    self.archive = _validate_archive(fn)
  File "C:\Users\allan.mesquita\AppData\Local\Packages\PythonSoftwareFoundation.Python.3.10_qbz5n2kfra8p0\LocalCache\local-packages\Python310\site-packages\openpyxl\reader\excel.py", line 96, in _validate_archive
    archive = ZipFile(filename, 'r')
  File "C:\Program Files\WindowsApps\PythonSoftwareFoundation.Python.3.10_3.10.1264.0_x64__qbz5n2kfra8p0\lib\zipfile.py", line 1249, in __init__
    self.fp = io.open(file, filemode)
FileNotFoundError: [Errno 2] No such file or directory: 'C:\\Users\\allan.mesquita\\NTT\\@AM BR Services and Operations - Privado\\GESTÃO DE ESTOQUE\\100 BcoDados\\003 Evidencias\\06 Lixeira\\Testes\\01 Processamento202204051510 33220305437734000580550010000026611100018356_Expedição.xlsx'
