2022-07-20 12:03:10,478 - [Errno 2] No such file or directory: 'C:\\Users\\allan.mesquita\\OneDrive - NTT\\Privado\\GESTÃO DE ESTOQUE\\002 Evidências\\tblEvidenciaRecebimento.xlsm'
Traceback (most recent call last):
  File "C:\Users\allan.mesquita\OneDrive - NTT\Documents\Projetos\Automacao_Evidencias\Script\main_v2.py", line 132, in <module>
    resultado = fuctions.atualizar(tblPA, aba_tblPA, path, file_name, df_mastersaf, v17)
  File "C:\Users\allan.mesquita\OneDrive - NTT\Documents\Projetos\Automacao_Evidencias\Script\Modulos\fuctions.py", line 85, in atualizar
    resultado = validacao.rec_validation(aba, qtd_linhas)
  File "C:\Users\allan.mesquita\OneDrive - NTT\Documents\Projetos\Automacao_Evidencias\Script\Modulos\validacao.py", line 50, in rec_validation
    dfTblRec = pd.read_excel("C:\\Users\\allan.mesquita\\OneDrive - NTT\\Privado\\GESTÃO DE ESTOQUE\\002 Evidências\\tblEvidenciaRecebimento.xlsm")  # Diretórios trocados após atualização no OneDrive 06.06.2022
  File "C:\Users\allan.mesquita\AppData\Local\Packages\PythonSoftwareFoundation.Python.3.10_qbz5n2kfra8p0\LocalCache\local-packages\Python310\site-packages\pandas\util\_decorators.py", line 311, in wrapper
    return func(*args, **kwargs)
  File "C:\Users\allan.mesquita\AppData\Local\Packages\PythonSoftwareFoundation.Python.3.10_qbz5n2kfra8p0\LocalCache\local-packages\Python310\site-packages\pandas\io\excel\_base.py", line 457, in read_excel
    io = ExcelFile(io, storage_options=storage_options, engine=engine)
  File "C:\Users\allan.mesquita\AppData\Local\Packages\PythonSoftwareFoundation.Python.3.10_qbz5n2kfra8p0\LocalCache\local-packages\Python310\site-packages\pandas\io\excel\_base.py", line 1376, in __init__
    ext = inspect_excel_format(
  File "C:\Users\allan.mesquita\AppData\Local\Packages\PythonSoftwareFoundation.Python.3.10_qbz5n2kfra8p0\LocalCache\local-packages\Python310\site-packages\pandas\io\excel\_base.py", line 1250, in inspect_excel_format
    with get_handle(
  File "C:\Users\allan.mesquita\AppData\Local\Packages\PythonSoftwareFoundation.Python.3.10_qbz5n2kfra8p0\LocalCache\local-packages\Python310\site-packages\pandas\io\common.py", line 798, in get_handle
    handle = open(handle, ioargs.mode)
FileNotFoundError: [Errno 2] No such file or directory: 'C:\\Users\\allan.mesquita\\OneDrive - NTT\\Privado\\GESTÃO DE ESTOQUE\\002 Evidências\\tblEvidenciaRecebimento.xlsm'
