2022-04-29 13:47:23,549 - [Errno 2] No such file or directory: 'C:\\Users\\allan.mesquita\\NTT\\@AM BR Services and Operations - Privado\\GESTÃO DE ESTOQUE\\100 BcoDados\\003 Evidencias\\01 Processamento\\202204281837 35220472381189001001550010040543731401916575_Recebimento.xlsx'
Traceback (most recent call last):
  File "C:\Users\allan.mesquita\OneDrive - NTT\Documents\Projetos\Automacao_Evidencias\Script\main_v2.py", line 107, in <module>
    wb = xl.open(path + file_name)
  File "C:\Users\allan.mesquita\AppData\Local\Packages\PythonSoftwareFoundation.Python.3.10_qbz5n2kfra8p0\LocalCache\local-packages\Python310\site-packages\openpyxl\reader\excel.py", line 315, in load_workbook
    reader = ExcelReader(filename, read_only, keep_vba,
  File "C:\Users\allan.mesquita\AppData\Local\Packages\PythonSoftwareFoundation.Python.3.10_qbz5n2kfra8p0\LocalCache\local-packages\Python310\site-packages\openpyxl\reader\excel.py", line 124, in __init__
    self.archive = _validate_archive(fn)
  File "C:\Users\allan.mesquita\AppData\Local\Packages\PythonSoftwareFoundation.Python.3.10_qbz5n2kfra8p0\LocalCache\local-packages\Python310\site-packages\openpyxl\reader\excel.py", line 96, in _validate_archive
    archive = ZipFile(filename, 'r')
  File "C:\Program Files\WindowsApps\PythonSoftwareFoundation.Python.3.10_3.10.1264.0_x64__qbz5n2kfra8p0\lib\zipfile.py", line 1249, in __init__
    self.fp = io.open(file, filemode)
FileNotFoundError: [Errno 2] No such file or directory: 'C:\\Users\\allan.mesquita\\NTT\\@AM BR Services and Operations - Privado\\GESTÃO DE ESTOQUE\\100 BcoDados\\003 Evidencias\\01 Processamento\\202204281837 35220472381189001001550010040543731401916575_Recebimento.xlsx'
