2022-07-27 11:01:14,166 - (-2147418111, 'Call was rejected by callee.', None, None)
Traceback (most recent call last):
  File "C:\Users\allan.mesquita\OneDrive - NTT\Documents\Projetos\Automacao_Evidencias\Script\main_v2.py", line 136, in <module>
    resultado = fuctions.atualizar(tblPA, aba_tblPA, path, file_name, df_mastersaf, v17)
  File "C:\Users\allan.mesquita\OneDrive - NTT\Documents\Projetos\Automacao_Evidencias\Script\Modulos\fuctions.py", line 11, in atualizar
    qtd_linhas_tblPA = aba_tblPA.UsedRange.Rows.Count
  File "C:\Users\allan.mesquita\AppData\Local\Packages\PythonSoftwareFoundation.Python.3.10_qbz5n2kfra8p0\LocalCache\local-packages\Python310\site-packages\win32com\client\dynamic.py", line 628, in __getattr__
    ret = self._oleobj_.Invoke(retEntry.dispid, 0, invoke_type, 1)
pywintypes.com_error: (-2147418111, 'Call was rejected by callee.', None, None)
